INFO _internal.py:88  * Running on http://127.0.0.1:5000/ (Press CTRL+C to quit)
INFO _internal.py:88 127.0.0.1 - - [27/Dec/2018 14:49:21] "GET / HTTP/1.1" 404 -
INFO _internal.py:88 127.0.0.1 - - [27/Dec/2018 14:49:21] "GET /favicon.ico HTTP/1.1" 404 -
INFO _internal.py:88 127.0.0.1 - - [27/Dec/2018 14:49:27] "GET / HTTP/1.1" 404 -
INFO _internal.py:88 127.0.0.1 - - [27/Dec/2018 14:49:27] "GET /favicon.ico HTTP/1.1" 404 -
INFO _internal.py:88  * Running on http://127.0.0.1:5000/ (Press CTRL+C to quit)
INFO _internal.py:88 127.0.0.1 - - [27/Dec/2018 14:51:56] "GET / HTTP/1.1" 200 -
INFO _internal.py:88 127.0.0.1 - - [27/Dec/2018 14:51:56] "GET /favicon.ico HTTP/1.1" 404 -
INFO _internal.py:88  * Running on http://127.0.0.1:5000/ (Press CTRL+C to quit)
INFO _internal.py:88 127.0.0.1 - - [27/Dec/2018 15:15:35] "GET / HTTP/1.1" 200 -
INFO _internal.py:88 127.0.0.1 - - [27/Dec/2018 15:15:35] "GET /favicon.ico HTTP/1.1" 404 -
INFO _internal.py:88  * Running on http://127.0.0.1:5000/ (Press CTRL+C to quit)
ERROR app.py:1423 Exception on / [GET]
Traceback (most recent call last):
  File "/home/python/.virtualenvs/Flask_py3.5/lib/python3.5/site-packages/redis/connection.py", line 184, in _read_from_socket
    raise socket.error(SERVER_CLOSED_CONNECTION_ERROR)
OSError: Connection closed by server.

During handling of the above exception, another exception occurred:

Traceback (most recent call last):
  File "/home/python/.virtualenvs/Flask_py3.5/lib/python3.5/site-packages/redis/client.py", line 755, in execute_command
    return self.parse_response(connection, command_name, **options)
  File "/home/python/.virtualenvs/Flask_py3.5/lib/python3.5/site-packages/redis/client.py", line 768, in parse_response
    response = connection.read_response()
  File "/home/python/.virtualenvs/Flask_py3.5/lib/python3.5/site-packages/redis/connection.py", line 636, in read_response
    raise e
  File "/home/python/.virtualenvs/Flask_py3.5/lib/python3.5/site-packages/redis/connection.py", line 633, in read_response
    response = self._parser.read_response()
  File "/home/python/.virtualenvs/Flask_py3.5/lib/python3.5/site-packages/redis/connection.py", line 291, in read_response
    response = self._buffer.readline()
  File "/home/python/.virtualenvs/Flask_py3.5/lib/python3.5/site-packages/redis/connection.py", line 223, in readline
    self._read_from_socket()
  File "/home/python/.virtualenvs/Flask_py3.5/lib/python3.5/site-packages/redis/connection.py", line 198, in _read_from_socket
    (e.args,))
redis.exceptions.ConnectionError: Error while reading from socket: ('Connection closed by server.',)

During handling of the above exception, another exception occurred:

Traceback (most recent call last):
  File "/home/python/.virtualenvs/Flask_py3.5/lib/python3.5/site-packages/redis/connection.py", line 184, in _read_from_socket
    raise socket.error(SERVER_CLOSED_CONNECTION_ERROR)
OSError: Connection closed by server.

During handling of the above exception, another exception occurred:

Traceback (most recent call last):
  File "/home/python/.virtualenvs/Flask_py3.5/lib/python3.5/site-packages/flask/app.py", line 1817, in wsgi_app
    response = self.full_dispatch_request()
  File "/home/python/.virtualenvs/Flask_py3.5/lib/python3.5/site-packages/flask/app.py", line 1477, in full_dispatch_request
    rv = self.handle_user_exception(e)
  File "/home/python/.virtualenvs/Flask_py3.5/lib/python3.5/site-packages/flask/app.py", line 1381, in handle_user_exception
    reraise(exc_type, exc_value, tb)
  File "/home/python/.virtualenvs/Flask_py3.5/lib/python3.5/site-packages/flask/_compat.py", line 33, in reraise
    raise value
  File "/home/python/.virtualenvs/Flask_py3.5/lib/python3.5/site-packages/flask/app.py", line 1475, in full_dispatch_request
    rv = self.dispatch_request()
  File "/home/python/.virtualenvs/Flask_py3.5/lib/python3.5/site-packages/flask/app.py", line 1461, in dispatch_request
    return self.view_functions[rule.endpoint](**req.view_args)
  File "/home/python/Desktop/Flask/F2/flask/info/modules/index/views.py", line 7, in index
    redis_store.set('nam','2haha')
  File "/home/python/.virtualenvs/Flask_py3.5/lib/python3.5/site-packages/redis/client.py", line 1394, in set
    return self.execute_command('SET', *pieces)
  File "/home/python/.virtualenvs/Flask_py3.5/lib/python3.5/site-packages/redis/client.py", line 761, in execute_command
    return self.parse_response(connection, command_name, **options)
  File "/home/python/.virtualenvs/Flask_py3.5/lib/python3.5/site-packages/redis/client.py", line 768, in parse_response
    response = connection.read_response()
  File "/home/python/.virtualenvs/Flask_py3.5/lib/python3.5/site-packages/redis/connection.py", line 636, in read_response
    raise e
  File "/home/python/.virtualenvs/Flask_py3.5/lib/python3.5/site-packages/redis/connection.py", line 633, in read_response
    response = self._parser.read_response()
  File "/home/python/.virtualenvs/Flask_py3.5/lib/python3.5/site-packages/redis/connection.py", line 291, in read_response
    response = self._buffer.readline()
  File "/home/python/.virtualenvs/Flask_py3.5/lib/python3.5/site-packages/redis/connection.py", line 223, in readline
    self._read_from_socket()
  File "/home/python/.virtualenvs/Flask_py3.5/lib/python3.5/site-packages/redis/connection.py", line 198, in _read_from_socket
    (e.args,))
redis.exceptions.ConnectionError: Error while reading from socket: ('Connection closed by server.',)
INFO _internal.py:88 127.0.0.1 - - [27/Dec/2018 21:30:16] "GET / HTTP/1.1" 500 -
INFO _internal.py:88 127.0.0.1 - - [27/Dec/2018 21:30:16] "GET /favicon.ico HTTP/1.1" 404 -
INFO _internal.py:88  * Running on http://127.0.0.1:5000/ (Press CTRL+C to quit)
INFO _internal.py:88 127.0.0.1 - - [27/Dec/2018 21:32:06] "GET / HTTP/1.1" 200 -
INFO _internal.py:88 127.0.0.1 - - [27/Dec/2018 21:32:06] "GET /favicon.ico HTTP/1.1" 404 -
INFO _internal.py:88  * Running on http://127.0.0.1:5000/ (Press CTRL+C to quit)
ERROR app.py:1423 Exception on / [GET]
Traceback (most recent call last):
  File "/home/python/.virtualenvs/Flask_py3.5/lib/python3.5/site-packages/redis/connection.py", line 184, in _read_from_socket
    raise socket.error(SERVER_CLOSED_CONNECTION_ERROR)
OSError: Connection closed by server.

During handling of the above exception, another exception occurred:

Traceback (most recent call last):
  File "/home/python/.virtualenvs/Flask_py3.5/lib/python3.5/site-packages/redis/client.py", line 755, in execute_command
    return self.parse_response(connection, command_name, **options)
  File "/home/python/.virtualenvs/Flask_py3.5/lib/python3.5/site-packages/redis/client.py", line 768, in parse_response
    response = connection.read_response()
  File "/home/python/.virtualenvs/Flask_py3.5/lib/python3.5/site-packages/redis/connection.py", line 636, in read_response
    raise e
  File "/home/python/.virtualenvs/Flask_py3.5/lib/python3.5/site-packages/redis/connection.py", line 633, in read_response
    response = self._parser.read_response()
  File "/home/python/.virtualenvs/Flask_py3.5/lib/python3.5/site-packages/redis/connection.py", line 291, in read_response
    response = self._buffer.readline()
  File "/home/python/.virtualenvs/Flask_py3.5/lib/python3.5/site-packages/redis/connection.py", line 223, in readline
    self._read_from_socket()
  File "/home/python/.virtualenvs/Flask_py3.5/lib/python3.5/site-packages/redis/connection.py", line 198, in _read_from_socket
    (e.args,))
redis.exceptions.ConnectionError: Error while reading from socket: ('Connection closed by server.',)

During handling of the above exception, another exception occurred:

Traceback (most recent call last):
  File "/home/python/.virtualenvs/Flask_py3.5/lib/python3.5/site-packages/redis/connection.py", line 184, in _read_from_socket
    raise socket.error(SERVER_CLOSED_CONNECTION_ERROR)
OSError: Connection closed by server.

During handling of the above exception, another exception occurred:

Traceback (most recent call last):
  File "/home/python/.virtualenvs/Flask_py3.5/lib/python3.5/site-packages/flask/app.py", line 1817, in wsgi_app
    response = self.full_dispatch_request()
  File "/home/python/.virtualenvs/Flask_py3.5/lib/python3.5/site-packages/flask/app.py", line 1477, in full_dispatch_request
    rv = self.handle_user_exception(e)
  File "/home/python/.virtualenvs/Flask_py3.5/lib/python3.5/site-packages/flask/app.py", line 1381, in handle_user_exception
    reraise(exc_type, exc_value, tb)
  File "/home/python/.virtualenvs/Flask_py3.5/lib/python3.5/site-packages/flask/_compat.py", line 33, in reraise
    raise value
  File "/home/python/.virtualenvs/Flask_py3.5/lib/python3.5/site-packages/flask/app.py", line 1475, in full_dispatch_request
    rv = self.dispatch_request()
  File "/home/python/.virtualenvs/Flask_py3.5/lib/python3.5/site-packages/flask/app.py", line 1461, in dispatch_request
    return self.view_functions[rule.endpoint](**req.view_args)
  File "/home/python/Desktop/Flask/F2/flask/info/modules/index/views.py", line 7, in index
    redis_store.set('nam','2haha')
  File "/home/python/.virtualenvs/Flask_py3.5/lib/python3.5/site-packages/redis/client.py", line 1394, in set
    return self.execute_command('SET', *pieces)
  File "/home/python/.virtualenvs/Flask_py3.5/lib/python3.5/site-packages/redis/client.py", line 761, in execute_command
    return self.parse_response(connection, command_name, **options)
  File "/home/python/.virtualenvs/Flask_py3.5/lib/python3.5/site-packages/redis/client.py", line 768, in parse_response
    response = connection.read_response()
  File "/home/python/.virtualenvs/Flask_py3.5/lib/python3.5/site-packages/redis/connection.py", line 636, in read_response
    raise e
  File "/home/python/.virtualenvs/Flask_py3.5/lib/python3.5/site-packages/redis/connection.py", line 633, in read_response
    response = self._parser.read_response()
  File "/home/python/.virtualenvs/Flask_py3.5/lib/python3.5/site-packages/redis/connection.py", line 291, in read_response
    response = self._buffer.readline()
  File "/home/python/.virtualenvs/Flask_py3.5/lib/python3.5/site-packages/redis/connection.py", line 223, in readline
    self._read_from_socket()
  File "/home/python/.virtualenvs/Flask_py3.5/lib/python3.5/site-packages/redis/connection.py", line 198, in _read_from_socket
    (e.args,))
redis.exceptions.ConnectionError: Error while reading from socket: ('Connection closed by server.',)
INFO _internal.py:88 127.0.0.1 - - [27/Dec/2018 21:33:41] "GET / HTTP/1.1" 500 -
INFO _internal.py:88 127.0.0.1 - - [27/Dec/2018 21:33:41] "GET /favicon.ico HTTP/1.1" 404 -
INFO _internal.py:88  * Running on http://127.0.0.1:5000/ (Press CTRL+C to quit)
ERROR app.py:1423 Exception on / [GET]
Traceback (most recent call last):
  File "/home/python/.virtualenvs/Flask_py3.5/lib/python3.5/site-packages/redis/connection.py", line 184, in _read_from_socket
    raise socket.error(SERVER_CLOSED_CONNECTION_ERROR)
OSError: Connection closed by server.

During handling of the above exception, another exception occurred:

Traceback (most recent call last):
  File "/home/python/.virtualenvs/Flask_py3.5/lib/python3.5/site-packages/redis/client.py", line 755, in execute_command
    return self.parse_response(connection, command_name, **options)
  File "/home/python/.virtualenvs/Flask_py3.5/lib/python3.5/site-packages/redis/client.py", line 768, in parse_response
    response = connection.read_response()
  File "/home/python/.virtualenvs/Flask_py3.5/lib/python3.5/site-packages/redis/connection.py", line 636, in read_response
    raise e
  File "/home/python/.virtualenvs/Flask_py3.5/lib/python3.5/site-packages/redis/connection.py", line 633, in read_response
    response = self._parser.read_response()
  File "/home/python/.virtualenvs/Flask_py3.5/lib/python3.5/site-packages/redis/connection.py", line 291, in read_response
    response = self._buffer.readline()
  File "/home/python/.virtualenvs/Flask_py3.5/lib/python3.5/site-packages/redis/connection.py", line 223, in readline
    self._read_from_socket()
  File "/home/python/.virtualenvs/Flask_py3.5/lib/python3.5/site-packages/redis/connection.py", line 198, in _read_from_socket
    (e.args,))
redis.exceptions.ConnectionError: Error while reading from socket: ('Connection closed by server.',)

During handling of the above exception, another exception occurred:

Traceback (most recent call last):
  File "/home/python/.virtualenvs/Flask_py3.5/lib/python3.5/site-packages/redis/connection.py", line 184, in _read_from_socket
    raise socket.error(SERVER_CLOSED_CONNECTION_ERROR)
OSError: Connection closed by server.

During handling of the above exception, another exception occurred:

Traceback (most recent call last):
  File "/home/python/.virtualenvs/Flask_py3.5/lib/python3.5/site-packages/flask/app.py", line 1817, in wsgi_app
    response = self.full_dispatch_request()
  File "/home/python/.virtualenvs/Flask_py3.5/lib/python3.5/site-packages/flask/app.py", line 1477, in full_dispatch_request
    rv = self.handle_user_exception(e)
  File "/home/python/.virtualenvs/Flask_py3.5/lib/python3.5/site-packages/flask/app.py", line 1381, in handle_user_exception
    reraise(exc_type, exc_value, tb)
  File "/home/python/.virtualenvs/Flask_py3.5/lib/python3.5/site-packages/flask/_compat.py", line 33, in reraise
    raise value
  File "/home/python/.virtualenvs/Flask_py3.5/lib/python3.5/site-packages/flask/app.py", line 1475, in full_dispatch_request
    rv = self.dispatch_request()
  File "/home/python/.virtualenvs/Flask_py3.5/lib/python3.5/site-packages/flask/app.py", line 1461, in dispatch_request
    return self.view_functions[rule.endpoint](**req.view_args)
  File "/home/python/Desktop/Flask/F2/flask/info/modules/index/views.py", line 7, in index
    redis_store.set('nam','2haha')
  File "/home/python/.virtualenvs/Flask_py3.5/lib/python3.5/site-packages/redis/client.py", line 1394, in set
    return self.execute_command('SET', *pieces)
  File "/home/python/.virtualenvs/Flask_py3.5/lib/python3.5/site-packages/redis/client.py", line 761, in execute_command
    return self.parse_response(connection, command_name, **options)
  File "/home/python/.virtualenvs/Flask_py3.5/lib/python3.5/site-packages/redis/client.py", line 768, in parse_response
    response = connection.read_response()
  File "/home/python/.virtualenvs/Flask_py3.5/lib/python3.5/site-packages/redis/connection.py", line 636, in read_response
    raise e
  File "/home/python/.virtualenvs/Flask_py3.5/lib/python3.5/site-packages/redis/connection.py", line 633, in read_response
    response = self._parser.read_response()
  File "/home/python/.virtualenvs/Flask_py3.5/lib/python3.5/site-packages/redis/connection.py", line 291, in read_response
    response = self._buffer.readline()
  File "/home/python/.virtualenvs/Flask_py3.5/lib/python3.5/site-packages/redis/connection.py", line 223, in readline
    self._read_from_socket()
  File "/home/python/.virtualenvs/Flask_py3.5/lib/python3.5/site-packages/redis/connection.py", line 198, in _read_from_socket
    (e.args,))
redis.exceptions.ConnectionError: Error while reading from socket: ('Connection closed by server.',)
INFO _internal.py:88 127.0.0.1 - - [27/Dec/2018 21:41:30] "GET / HTTP/1.1" 500 -
INFO _internal.py:88 127.0.0.1 - - [27/Dec/2018 21:41:30] "GET /favicon.ico HTTP/1.1" 404 -
INFO _internal.py:88  * Running on http://127.0.0.1:5000/ (Press CTRL+C to quit)
INFO _internal.py:88  * Restarting with stat
WARNING _internal.py:88  * Debugger is active!
INFO _internal.py:88  * Debugger PIN: 437-785-630
INFO _internal.py:88 127.0.0.1 - - [27/Dec/2018 21:46:30] "GET / HTTP/1.1" 500 -
INFO _internal.py:88 127.0.0.1 - - [27/Dec/2018 21:46:30] "GET /?__debugger__=yes&cmd=resource&f=style.css HTTP/1.1" 200 -
INFO _internal.py:88 127.0.0.1 - - [27/Dec/2018 21:46:30] "GET /?__debugger__=yes&cmd=resource&f=jquery.js HTTP/1.1" 200 -
INFO _internal.py:88 127.0.0.1 - - [27/Dec/2018 21:46:31] "GET /?__debugger__=yes&cmd=resource&f=debugger.js HTTP/1.1" 200 -
INFO _internal.py:88 127.0.0.1 - - [27/Dec/2018 21:46:31] "GET /?__debugger__=yes&cmd=resource&f=console.png HTTP/1.1" 200 -
INFO _internal.py:88 127.0.0.1 - - [27/Dec/2018 21:46:31] "GET /?__debugger__=yes&cmd=resource&f=console.png HTTP/1.1" 200 -
INFO _internal.py:88  * Running on http://127.0.0.1:5000/ (Press CTRL+C to quit)
INFO _internal.py:88  * Restarting with stat
WARNING _internal.py:88  * Debugger is active!
INFO _internal.py:88  * Debugger PIN: 437-785-630
INFO _internal.py:88 127.0.0.1 - - [27/Dec/2018 21:48:00] "GET / HTTP/1.1" 500 -
INFO _internal.py:88 127.0.0.1 - - [27/Dec/2018 21:48:00] "GET /?__debugger__=yes&cmd=resource&f=jquery.js HTTP/1.1" 200 -
INFO _internal.py:88 127.0.0.1 - - [27/Dec/2018 21:48:00] "GET /?__debugger__=yes&cmd=resource&f=debugger.js HTTP/1.1" 200 -
INFO _internal.py:88 127.0.0.1 - - [27/Dec/2018 21:48:00] "GET /?__debugger__=yes&cmd=resource&f=style.css HTTP/1.1" 200 -
INFO _internal.py:88 127.0.0.1 - - [27/Dec/2018 21:48:01] "GET /?__debugger__=yes&cmd=resource&f=console.png HTTP/1.1" 200 -
INFO _internal.py:88  * Detected change in '/home/python/Desktop/Flask/F2/flask/config.py', reloading
INFO _internal.py:88  * Restarting with stat
WARNING _internal.py:88  * Debugger is active!
INFO _internal.py:88  * Debugger PIN: 437-785-630
INFO _internal.py:88  * Running on http://127.0.0.1:5000/ (Press CTRL+C to quit)
INFO _internal.py:88  * Restarting with stat
WARNING _internal.py:88  * Debugger is active!
INFO _internal.py:88  * Debugger PIN: 437-785-630
INFO _internal.py:88 127.0.0.1 - - [27/Dec/2018 21:50:41] "GET / HTTP/1.1" 500 -
INFO _internal.py:88 127.0.0.1 - - [27/Dec/2018 21:50:41] "GET /?__debugger__=yes&cmd=resource&f=style.css HTTP/1.1" 200 -
INFO _internal.py:88 127.0.0.1 - - [27/Dec/2018 21:50:41] "GET /?__debugger__=yes&cmd=resource&f=jquery.js HTTP/1.1" 200 -
INFO _internal.py:88 127.0.0.1 - - [27/Dec/2018 21:50:41] "GET /?__debugger__=yes&cmd=resource&f=debugger.js HTTP/1.1" 200 -
INFO _internal.py:88 127.0.0.1 - - [27/Dec/2018 21:50:41] "GET /?__debugger__=yes&cmd=resource&f=console.png HTTP/1.1" 200 -
INFO _internal.py:88  * Running on http://127.0.0.1:5000/ (Press CTRL+C to quit)
INFO _internal.py:88  * Restarting with stat
WARNING _internal.py:88  * Debugger is active!
INFO _internal.py:88  * Debugger PIN: 437-785-630
INFO _internal.py:88 127.0.0.1 - - [27/Dec/2018 21:52:14] "GET / HTTP/1.1" 200 -
INFO _internal.py:88 127.0.0.1 - - [27/Dec/2018 21:52:14] "GET /favicon.ico HTTP/1.1" 404 -
INFO _internal.py:88  * Detected change in '/home/python/Desktop/Flask/F2/flask/config.py', reloading
INFO _internal.py:88  * Restarting with stat
WARNING _internal.py:88  * Debugger is active!
INFO _internal.py:88  * Debugger PIN: 437-785-630
